../usr/lib/python3.7/subprocess.py:883: ResourceWarning: subprocess 100020 is still running
  ResourceWarning, source=self)
ResourceWarning: Enable tracemalloc to get the object allocation traceback
/home/student/.local/lib/python3.7/site-packages/rfc3986/uri.py:97: ResourceWarning: unclosed <socket.socket fd=13, family=AddressFamily.AF_INET, type=SocketKind.SOCK_STREAM, proto=6, laddr=('127.0.0.1', 46550)>
  ref.encoding = encoding
ResourceWarning: Enable tracemalloc to get the object allocation traceback
/home/student/.local/lib/python3.7/site-packages/rfc3986/uri.py:97: ResourceWarning: unclosed <socket.socket fd=14, family=AddressFamily.AF_INET, type=SocketKind.SOCK_STREAM, proto=6, laddr=('127.0.0.1', 46552)>
  ref.encoding = encoding
ResourceWarning: Enable tracemalloc to get the object allocation traceback
/home/student/.local/lib/python3.7/site-packages/rfc3986/uri.py:97: ResourceWarning: unclosed <socket.socket fd=15, family=AddressFamily.AF_INET, type=SocketKind.SOCK_STREAM, proto=6, laddr=('127.0.0.1', 46554)>
  ref.encoding = encoding
ResourceWarning: Enable tracemalloc to get the object allocation traceback
/home/student/.local/lib/python3.7/site-packages/rfc3986/uri.py:97: ResourceWarning: unclosed <socket.socket fd=16, family=AddressFamily.AF_INET, type=SocketKind.SOCK_STREAM, proto=6, laddr=('127.0.0.1', 46556)>
  ref.encoding = encoding
ResourceWarning: Enable tracemalloc to get the object allocation traceback
/home/student/.local/lib/python3.7/site-packages/rfc3986/uri.py:97: ResourceWarning: unclosed <socket.socket fd=17, family=AddressFamily.AF_INET, type=SocketKind.SOCK_STREAM, proto=6, laddr=('127.0.0.1', 46558)>
  ref.encoding = encoding
ResourceWarning: Enable tracemalloc to get the object allocation traceback
/home/student/.local/lib/python3.7/site-packages/rfc3986/uri.py:97: ResourceWarning: unclosed <socket.socket fd=18, family=AddressFamily.AF_INET, type=SocketKind.SOCK_STREAM, proto=6, laddr=('127.0.0.1', 46560)>
  ref.encoding = encoding
ResourceWarning: Enable tracemalloc to get the object allocation traceback
/home/student/.local/lib/python3.7/site-packages/rfc3986/uri.py:97: ResourceWarning: unclosed <socket.socket fd=19, family=AddressFamily.AF_INET, type=SocketKind.SOCK_STREAM, proto=6, laddr=('127.0.0.1', 46562)>
  ref.encoding = encoding
ResourceWarning: Enable tracemalloc to get the object allocation traceback
/home/student/.local/lib/python3.7/site-packages/rfc3986/uri.py:97: ResourceWarning: unclosed <socket.socket fd=20, family=AddressFamily.AF_INET, type=SocketKind.SOCK_STREAM, proto=6, laddr=('127.0.0.1', 46564)>
  ref.encoding = encoding
ResourceWarning: Enable tracemalloc to get the object allocation traceback
/home/student/.local/lib/python3.7/site-packages/rfc3986/uri.py:97: ResourceWarning: unclosed <socket.socket fd=21, family=AddressFamily.AF_INET, type=SocketKind.SOCK_STREAM, proto=6, laddr=('127.0.0.1', 46566)>
  ref.encoding = encoding
ResourceWarning: Enable tracemalloc to get the object allocation traceback
/home/student/.local/lib/python3.7/site-packages/rfc3986/uri.py:97: ResourceWarning: unclosed <socket.socket fd=22, family=AddressFamily.AF_INET, type=SocketKind.SOCK_STREAM, proto=6, laddr=('127.0.0.1', 46568)>
  ref.encoding = encoding
ResourceWarning: Enable tracemalloc to get the object allocation traceback
/usr/lib/python3.7/asyncio/selector_events.py:658: ResourceWarning: unclosed transport <_SelectorSocketTransport fd=9>
  source=self)
ResourceWarning: Enable tracemalloc to get the object allocation traceback
/usr/lib/python3.7/asyncio/selector_events.py:658: ResourceWarning: unclosed transport <_SelectorSocketTransport fd=10>
  source=self)
ResourceWarning: Enable tracemalloc to get the object allocation traceback
/usr/lib/python3.7/asyncio/selector_events.py:658: ResourceWarning: unclosed transport <_SelectorSocketTransport fd=11>
  source=self)
ResourceWarning: Enable tracemalloc to get the object allocation traceback
/usr/lib/python3.7/asyncio/selector_events.py:658: ResourceWarning: unclosed transport <_SelectorSocketTransport fd=12>
  source=self)
ResourceWarning: Enable tracemalloc to get the object allocation traceback
/usr/lib/python3.7/asyncio/selector_events.py:658: ResourceWarning: unclosed transport <_SelectorSocketTransport fd=13>
  source=self)
ResourceWarning: Enable tracemalloc to get the object allocation traceback
/usr/lib/python3.7/asyncio/selector_events.py:658: ResourceWarning: unclosed transport <_SelectorSocketTransport fd=14>
  source=self)
ResourceWarning: Enable tracemalloc to get the object allocation traceback
/usr/lib/python3.7/asyncio/selector_events.py:658: ResourceWarning: unclosed transport <_SelectorSocketTransport fd=15>
  source=self)
ResourceWarning: Enable tracemalloc to get the object allocation traceback
/usr/lib/python3.7/asyncio/selector_events.py:658: ResourceWarning: unclosed transport <_SelectorSocketTransport fd=16>
  source=self)
ResourceWarning: Enable tracemalloc to get the object allocation traceback
/usr/lib/python3.7/asyncio/selector_events.py:658: ResourceWarning: unclosed transport <_SelectorSocketTransport fd=17>
  source=self)
ResourceWarning: Enable tracemalloc to get the object allocation traceback
/usr/lib/python3.7/asyncio/selector_events.py:658: ResourceWarning: unclosed transport <_SelectorSocketTransport fd=18>
  source=self)
ResourceWarning: Enable tracemalloc to get the object allocation traceback
/usr/lib/python3.7/asyncio/selector_events.py:658: ResourceWarning: unclosed transport <_SelectorSocketTransport fd=19>
  source=self)
ResourceWarning: Enable tracemalloc to get the object allocation traceback
/usr/lib/python3.7/asyncio/selector_events.py:658: ResourceWarning: unclosed transport <_SelectorSocketTransport fd=20>
  source=self)
ResourceWarning: Enable tracemalloc to get the object allocation traceback
/usr/lib/python3.7/asyncio/selector_events.py:658: ResourceWarning: unclosed transport <_SelectorSocketTransport fd=21>
  source=self)
ResourceWarning: Enable tracemalloc to get the object allocation traceback
/usr/lib/python3.7/asyncio/selector_events.py:658: ResourceWarning: unclosed transport <_SelectorSocketTransport fd=22>
  source=self)
ResourceWarning: Enable tracemalloc to get the object allocation traceback
/usr/lib/python3.7/subprocess.py:883: ResourceWarning: subprocess 100051 is still running
  ResourceWarning, source=self)
ResourceWarning: Enable tracemalloc to get the object allocation traceback
/usr/lib/python3.7/asyncio/selector_events.py:658: ResourceWarning: unclosed transport <_SelectorSocketTransport fd=23>
  source=self)
ResourceWarning: Enable tracemalloc to get the object allocation traceback
../usr/lib/python3.7/subprocess.py:883: ResourceWarning: subprocess 100110 is still running
  ResourceWarning, source=self)
ResourceWarning: Enable tracemalloc to get the object allocation traceback
./usr/lib/python3.7/asyncio/selector_events.py:658: ResourceWarning: unclosed transport <_SelectorSocketTransport fd=26>
  source=self)
ResourceWarning: Enable tracemalloc to get the object allocation traceback
/usr/lib/python3.7/asyncio/selector_events.py:658: ResourceWarning: unclosed transport <_SelectorSocketTransport fd=28>
  source=self)
ResourceWarning: Enable tracemalloc to get the object allocation traceback
/usr/lib/python3.7/subprocess.py:883: ResourceWarning: subprocess 100159 is still running
  ResourceWarning, source=self)
ResourceWarning: Enable tracemalloc to get the object allocation traceback
../usr/lib/python3.7/asyncio/selector_events.py:658: ResourceWarning: unclosed transport <_SelectorSocketTransport fd=35>
  source=self)
ResourceWarning: Enable tracemalloc to get the object allocation traceback
/usr/lib/python3.7/subprocess.py:883: ResourceWarning: subprocess 100224 is still running
  ResourceWarning, source=self)
ResourceWarning: Enable tracemalloc to get the object allocation traceback
/usr/lib/python3.7/subprocess.py:883: ResourceWarning: subprocess 100070 is still running
  ResourceWarning, source=self)
ResourceWarning: Enable tracemalloc to get the object allocation traceback
/usr/lib/python3.7/subprocess.py:883: ResourceWarning: subprocess 100193 is still running
  ResourceWarning, source=self)
ResourceWarning: Enable tracemalloc to get the object allocation traceback
/usr/lib/python3.7/asyncio/selector_events.py:658: ResourceWarning: unclosed transport <_SelectorSocketTransport fd=25>
  source=self)
ResourceWarning: Enable tracemalloc to get the object allocation traceback
/usr/lib/python3.7/asyncio/selector_events.py:658: ResourceWarning: unclosed transport <_SelectorSocketTransport fd=24>
  source=self)
ResourceWarning: Enable tracemalloc to get the object allocation traceback
/usr/lib/python3.7/asyncio/selector_events.py:658: ResourceWarning: unclosed transport <_SelectorSocketTransport fd=27>
  source=self)
ResourceWarning: Enable tracemalloc to get the object allocation traceback
/usr/lib/python3.7/asyncio/selector_events.py:658: ResourceWarning: unclosed transport <_SelectorSocketTransport fd=29>
  source=self)
ResourceWarning: Enable tracemalloc to get the object allocation traceback
/usr/lib/python3.7/asyncio/selector_events.py:658: ResourceWarning: unclosed transport <_SelectorSocketTransport fd=30>
  source=self)
ResourceWarning: Enable tracemalloc to get the object allocation traceback
/usr/lib/python3.7/asyncio/selector_events.py:658: ResourceWarning: unclosed transport <_SelectorSocketTransport fd=31>
  source=self)
ResourceWarning: Enable tracemalloc to get the object allocation traceback
/usr/lib/python3.7/asyncio/selector_events.py:658: ResourceWarning: unclosed transport <_SelectorSocketTransport fd=32>
  source=self)
ResourceWarning: Enable tracemalloc to get the object allocation traceback
/usr/lib/python3.7/asyncio/selector_events.py:658: ResourceWarning: unclosed transport <_SelectorSocketTransport fd=33>
  source=self)
ResourceWarning: Enable tracemalloc to get the object allocation traceback
/usr/lib/python3.7/asyncio/selector_events.py:658: ResourceWarning: unclosed transport <_SelectorSocketTransport fd=34>
  source=self)
ResourceWarning: Enable tracemalloc to get the object allocation traceback
/usr/lib/python3.7/subprocess.py:883: ResourceWarning: subprocess 100243 is still running
  ResourceWarning, source=self)
ResourceWarning: Enable tracemalloc to get the object allocation traceback
.bind failed
Open_listenfd error: Address already in use
/usr/lib/python3.7/subprocess.py:883: ResourceWarning: subprocess 100348 is still running
  ResourceWarning, source=self)
ResourceWarning: Enable tracemalloc to get the object allocation traceback
E./usr/lib/python3.7/subprocess.py:883: ResourceWarning: subprocess 100487 is still running
  ResourceWarning, source=self)
ResourceWarning: Enable tracemalloc to get the object allocation traceback
./usr/lib/python3.7/subprocess.py:883: ResourceWarning: subprocess 100490 is still running
  ResourceWarning, source=self)
ResourceWarning: Enable tracemalloc to get the object allocation traceback
./usr/lib/python3.7/subprocess.py:883: ResourceWarning: subprocess 100494 is still running
  ResourceWarning, source=self)
ResourceWarning: Enable tracemalloc to get the object allocation traceback
./usr/lib/python3.7/subprocess.py:883: ResourceWarning: subprocess 100497 is still running
  ResourceWarning, source=self)
ResourceWarning: Enable tracemalloc to get the object allocation traceback
./usr/lib/python3.7/subprocess.py:883: ResourceWarning: subprocess 100500 is still running
  ResourceWarning, source=self)
ResourceWarning: Enable tracemalloc to get the object allocation traceback

======================================================================
ERROR: test_time_full_queue (__main__.TestMultiThreaded)
----------------------------------------------------------------------
Traceback (most recent call last):
  File "/home/student/.local/lib/python3.7/site-packages/requests_async/adapters.py", line 55, in send
    timeout=timeout,
  File "/home/student/.local/lib/python3.7/site-packages/http3/interfaces.py", line 49, in request
    return await self.send(request, verify=verify, cert=cert, timeout=timeout)
  File "/home/student/.local/lib/python3.7/site-packages/http3/dispatch/connection_pool.py", line 130, in send
    raise exc
  File "/home/student/.local/lib/python3.7/site-packages/http3/dispatch/connection_pool.py", line 121, in send
    request, verify=verify, cert=cert, timeout=timeout
  File "/home/student/.local/lib/python3.7/site-packages/http3/dispatch/connection.py", line 53, in send
    await self.connect(verify=verify, cert=cert, timeout=timeout)
  File "/home/student/.local/lib/python3.7/site-packages/http3/dispatch/connection.py", line 82, in connect
    host, port, ssl_context, timeout
  File "/home/student/.local/lib/python3.7/site-packages/http3/concurrency.py", line 206, in connect
    timeout.connect_timeout,
  File "/usr/lib/python3.7/asyncio/tasks.py", line 414, in wait_for
    return await fut
  File "/usr/lib/python3.7/asyncio/streams.py", line 77, in open_connection
    lambda: protocol, host, port, **kwds)
  File "/usr/lib/python3.7/asyncio/base_events.py", line 954, in create_connection
    raise exceptions[0]
  File "/usr/lib/python3.7/asyncio/base_events.py", line 941, in create_connection
    await self.sock_connect(sock, address)
  File "/usr/lib/python3.7/asyncio/selector_events.py", line 464, in sock_connect
    return await fut
  File "/usr/lib/python3.7/asyncio/selector_events.py", line 494, in _sock_connect_cb
    raise OSError(err, f'Connect call failed {address}')
ConnectionRefusedError: [Errno 111] Connect call failed ('127.0.0.1', 8080)

During handling of the above exception, another exception occurred:

Traceback (most recent call last):
  File "./server_tests.py", line 226, in test_time_full_queue
    asyncio.run(self.make_requests(self.dyn_url, req_count))
  File "/usr/lib/python3.7/asyncio/runners.py", line 43, in run
    return loop.run_until_complete(main)
  File "/usr/lib/python3.7/asyncio/base_events.py", line 579, in run_until_complete
    return future.result()
  File "./server_tests.py", line 148, in make_requests
    raise res.e
  File "./server_tests.py", line 81, in make_req
    response = await requests.get(url)
  File "/home/student/.local/lib/python3.7/site-packages/requests_async/api.py", line 11, in get
    return await request("get", url, params=params, **kwargs)
  File "/home/student/.local/lib/python3.7/site-packages/requests_async/api.py", line 6, in request
    return await session.request(method=method, url=url, **kwargs)
  File "/home/student/.local/lib/python3.7/site-packages/requests_async/sessions.py", line 79, in request
    resp = await self.send(prep, **send_kwargs)
  File "/home/student/.local/lib/python3.7/site-packages/requests_async/sessions.py", line 136, in send
    r = await adapter.send(request, **kwargs)
  File "/home/student/.local/lib/python3.7/site-packages/requests_async/adapters.py", line 58, in send
    raise ConnectionError(err, request=request)
requests.exceptions.ConnectionError: [Errno 111] Connect call failed ('127.0.0.1', 8080)

----------------------------------------------------------------------
Ran 14 tests in 14.716s

FAILED (errors=1)
Setting up test:
	thread: 3
	queue size: 7
	policy: dh
Requesting url: http://localhost:8080/output.cgi
Requests succeeded: 7
Requests failed: 14
Setting up test:
	thread: 3
	queue size: 7
	policy: dh
Requesting url: http://localhost:8080/output.cgi
Requests succeeded: 7
Requests failed: 1
Setting up test:
	thread: 3
	queue size: 16
	policy: random
Requesting url: http://localhost:8080/output.cgi
Requests succeeded: 16
Requests failed: 8
Setting up test:
	thread: 3
	queue size: 16
	policy: random
Requesting url: http://localhost:8080/output.cgi
Requests succeeded: 16
Requests failed: 0
Setting up test:
	thread: 3
	queue size: 16
	policy: random
Requesting url: http://localhost:8080/output.cgi
Requests succeeded: 13
Requests failed: 4
Setting up test:
	thread: 3
	queue size: 7
	policy: dt
Requesting url: http://localhost:8080/output.cgi
Requests succeeded: 7
Requests failed: 14
Setting up test:
	thread: 3
	queue size: 7
	policy: dt
Requesting url: http://localhost:8080/output.cgi
Requests succeeded: 7
Requests failed: 1
Setting up test:
	thread: 3
	queue size: 80
	policy: dt
Requesting url: http://localhost:8080/output.cgi
Requests succeeded: 80
Requests failed: 0
Setting up test:
	thread: 9
	queue size: 80
	policy: dt
Requesting url: http://localhost:8080/output.cgi
Requests succeeded: 80
Requests failed: 0
Setting up test:
	thread: 3
	queue size: 80
	policy: dt
Requesting url: http://localhost:8080/output.cgi
Setting up test:
	thread: 1
	queue size: 1
	policy: dt
Setting up test:
	thread: 1
	queue size: 1
	policy: dt
Setting up test:
	thread: 1
	queue size: 1
	policy: dt
Setting up test:
	thread: 1
	queue size: 1
	policy: dt
Setting up test:
	thread: 1
	queue size: 1
	policy: dt
